2023-12-30 11:54:19,683 (WARNING) - django.request - Bad Request: /store/collections/
2023-12-30 11:54:20,707 (WARNING) - django.request - Unauthorized: /store/collections/
2023-12-30 11:54:20,707 (ERROR) - django.request - Internal Server Error: /store/collections/
Traceback (most recent call last):
  File "c:\Users\DELL\Desktop\devops\venv\Lib\site-packages\django\core\handlers\exception.py", line 55, in inner
    response = get_response(request)
               ^^^^^^^^^^^^^^^^^^^^^
  File "c:\Users\DELL\Desktop\devops\venv\Lib\site-packages\django\core\handlers\base.py", line 197, in _get_response
    response = wrapped_callback(request, *callback_args, **callback_kwargs)
               ^^^^^^^^^^^^^^^^^^^^^^^^^^^^^^^^^^^^^^^^^^^^^^^^^^^^^^^^^^^^
  File "c:\Users\DELL\Desktop\devops\venv\Lib\site-packages\django\views\decorators\csrf.py", line 65, in _view_wrapper
    return view_func(request, *args, **kwargs)
           ^^^^^^^^^^^^^^^^^^^^^^^^^^^^^^^^^^^
  File "c:\Users\DELL\Desktop\devops\venv\Lib\site-packages\rest_framework\viewsets.py", line 125, in view
    return self.dispatch(request, *args, **kwargs)
           ^^^^^^^^^^^^^^^^^^^^^^^^^^^^^^^^^^^^^^^
  File "c:\Users\DELL\Desktop\devops\venv\Lib\site-packages\rest_framework\views.py", line 509, in dispatch
    response = self.handle_exception(exc)
               ^^^^^^^^^^^^^^^^^^^^^^^^^^
  File "c:\Users\DELL\Desktop\devops\venv\Lib\site-packages\rest_framework\views.py", line 469, in handle_exception
    self.raise_uncaught_exception(exc)
  File "c:\Users\DELL\Desktop\devops\venv\Lib\site-packages\rest_framework\views.py", line 480, in raise_uncaught_exception
    raise exc
  File "c:\Users\DELL\Desktop\devops\venv\Lib\site-packages\rest_framework\views.py", line 506, in dispatch
    response = handler(request, *args, **kwargs)
               ^^^^^^^^^^^^^^^^^^^^^^^^^^^^^^^^^
  File "c:\Users\DELL\Desktop\devops\venv\Lib\site-packages\rest_framework\mixins.py", line 19, in create
    self.perform_create(serializer)
  File "c:\Users\DELL\Desktop\devops\venv\Lib\site-packages\rest_framework\mixins.py", line 24, in perform_create
    serializer.save()
  File "c:\Users\DELL\Desktop\devops\venv\Lib\site-packages\rest_framework\serializers.py", line 212, in save
    self.instance = self.create(validated_data)
                    ^^^^^^^^^^^^^^^^^^^^^^^^^^^
  File "c:\Users\DELL\Desktop\devops\venv\Lib\site-packages\rest_framework\serializers.py", line 962, in create
    instance = ModelClass._default_manager.create(**validated_data)
               ^^^^^^^^^^^^^^^^^^^^^^^^^^^^^^^^^^^^^^^^^^^^^^^^^^^^
  File "c:\Users\DELL\Desktop\devops\venv\Lib\site-packages\django\db\models\manager.py", line 87, in manager_method
    return getattr(self.get_queryset(), name)(*args, **kwargs)
           ^^^^^^^^^^^^^^^^^^^^^^^^^^^^^^^^^^^^^^^^^^^^^^^^^^^
  File "c:\Users\DELL\Desktop\devops\venv\Lib\site-packages\django\db\models\query.py", line 677, in create
    obj.save(force_insert=True, using=self.db)
  File "c:\Users\DELL\Desktop\devops\venv\Lib\site-packages\django\db\models\base.py", line 814, in save
    self.save_base(
  File "c:\Users\DELL\Desktop\devops\venv\Lib\site-packages\django\db\models\base.py", line 901, in save_base
    updated = self._save_table(
              ^^^^^^^^^^^^^^^^^
  File "c:\Users\DELL\Desktop\devops\venv\Lib\site-packages\django\db\models\base.py", line 1059, in _save_table
    results = self._do_insert(
              ^^^^^^^^^^^^^^^^
  File "c:\Users\DELL\Desktop\devops\venv\Lib\site-packages\django\db\models\base.py", line 1100, in _do_insert
    return manager._insert(
           ^^^^^^^^^^^^^^^^
  File "c:\Users\DELL\Desktop\devops\venv\Lib\site-packages\django\db\models\manager.py", line 87, in manager_method
    return getattr(self.get_queryset(), name)(*args, **kwargs)
           ^^^^^^^^^^^^^^^^^^^^^^^^^^^^^^^^^^^^^^^^^^^^^^^^^^^
  File "c:\Users\DELL\Desktop\devops\venv\Lib\site-packages\django\db\models\query.py", line 1845, in _insert
    return query.get_compiler(using=using).execute_sql(returning_fields)
           ^^^^^^^^^^^^^^^^^^^^^^^^^^^^^^^^^^^^^^^^^^^^^^^^^^^^^^^^^^^^^
  File "c:\Users\DELL\Desktop\devops\venv\Lib\site-packages\django\db\models\sql\compiler.py", line 1820, in execute_sql
    with self.connection.cursor() as cursor:
         ^^^^^^^^^^^^^^^^^^^^^^^^
  File "c:\Users\DELL\Desktop\devops\venv\Lib\site-packages\django\utils\asyncio.py", line 26, in inner
    return func(*args, **kwargs)
           ^^^^^^^^^^^^^^^^^^^^^
  File "c:\Users\DELL\Desktop\devops\venv\Lib\site-packages\django\db\backends\base\base.py", line 316, in cursor
    return self._cursor()
           ^^^^^^^^^^^^^^
  File "c:\Users\DELL\Desktop\devops\venv\Lib\site-packages\django\db\backends\base\base.py", line 292, in _cursor
    self.ensure_connection()
  File "c:\Users\DELL\desktop\devops\venv\Lib\site-packages\pytest_django\plugin.py", line 798, in _blocking_wrapper
    raise RuntimeError(
RuntimeError: Database access not allowed, use the "django_db" mark, or the "db" or "transactional_db" fixtures to enable it.
2023-12-30 11:54:22,728 (WARNING) - django.request - Bad Request: /store/collections/
2023-12-30 11:54:48,064 (WARNING) - django.request - Bad Request: /store/collections/
2023-12-30 11:55:35,185 (WARNING) - django.request - Bad Request: /store/collections/
